Workbook
Name Month: 'Рес.план'!$L$1

Sheet Рес.план
G1: Новые строки не вставлять. Вписывать в свободную строку снизу и ее перетаскивать при необходимости. | K1: max мес.факт> | L1: =IFERROR(__xludf.DUMMYFUNCTION("IMPORTRANGE(""https://docs.google.com/spreadsheets/d/1kEC_HJgReNpnVSEf-kbl8yf-9pL9ditjS0XzOedL4eE/edit?gid=1277221272#gid=1277221272"",""Предагрегат!N4"")"),"#REF!") -> #REF! | M1: Год: | N1: =index('Команда'!U1:CU1,match(N2,'Команда'!U2:CU2,0)) -> #REF! | O1: =index('Команда'!V1:CV1,match(O2,'Команда'!V2:CV2,0)) -> #REF! | P1: =index('Команда'!W1:CW1,match(P2,'Команда'!W2:CW2,0)) -> #REF! | Q1: {=index('Команда'!X1:CW1,match(Q2,'Команда'!X2:CW2,0))} -> #REF! | R1: {=index('Команда'!Y1:CW1,match(R2,'Команда'!Y2:CW2,0))} -> #REF! | S1: {=index('Команда'!Z1:CW1,match(S2,'Команда'!Z2:CW2,0))} -> #REF! | T1: {=index('Команда'!AA1:CW1,match(T2,'Команда'!AA2:CW2,0))} -> #REF! | U1: {=index('Команда'!AB1:CW1,match(U2,'Команда'!AB2:CW2,0))} -> #REF! | V1: {=index('Команда'!AC1:CW1,match(V2,'Команда'!AC2:CW2,0))} -> #REF! | W1: {=index('Команда'!AD1:CW1,match(W2,'Команда'!AD2:CW2,0))} -> #REF! | X1: {=index('Команда'!AE1:CW1,match(X2,'Команда'!AE2:CW2,0))} -> #REF! | Y1: {=index('Команда'!AF1:CW1,match(Y2,'Команда'!AF2:CW2,0))} -> #REF! | Z1: 15 | AA1: 19 | AB1: 21 | AC1: 22 | AD1: 19 | AE1: 21 | AF1: 23 | AG1: 21 | AH1: 22 | AI1: 22 | AJ1: 20 | AK1: 22 | AL1: <<Рабочих дней
A2: A/D | B2: Роль | C2: Пул | D2: Тип | E2: Ответственный | F2: Верх.стрим | G2: Стрим | H2: Задача | I2: PM | J2: Сотрудник | K2: in? | L2: Sum | M2: 2026 | N2: 45658 | O2: 45689 | P2: 45717 | Q2: 45748 | R2: 45778 | S2: 45809 | T2: 45839 | U2: 45870 | V2: 45901 | W2: 45931 | X2: 45962 | Y2: 45992 | Z2: 46023 | AA2: 46054 | AB2: 46082 | AC2: 46113 | AD2: 46143 | AE2: 46174 | AF2: 46204 | AG2: 46235 | AH2: 46266 | AI2: 46296 | AJ2: 46327 | AK2: 46357
A3: D | B3: SD ACRM | C3: ПП | D3: fix | E3: ACRM | F3: ACRM FIX | G3: ACRM FIX (Борисевич) | H3: ACRM FIX (Борисевич) | I3: Яковлева Елена | J3: Алексеев Георгий | K3: =if(H3="","",NOT(ISNA(VLOOKUP(J3,'Команда'!G:G,1,false)))) -> TRUE | L3: =if(H3="","",sumifs(N3:BO3,N$2:BO$2,">"&$L$1)) -> 0 | M3: {=IF(H3="","",SUMif(year(N$2:BO$2),M$2,N3:BO3))} -> 0 | N3: 15.88 | O3: 14.5 | P3: 4.87 | Q3: 11
A4: D | B4: SD ACRM | C4: ПП | D4: fix | E4: ACRM | F4: ACRM Support | G4: ACRM Support (Борисевич) | H4: ACRM Support (Борисевич) | I4: Яковлева Елена | J4: Алексеев Георгий | K4: =if(H4="","",NOT(ISNA(VLOOKUP(J4,'Команда'!G:G,1,false)))) -> TRUE | L4: =if(H4="","",sumifs(N4:BO4,N$2:BO$2,">"&$L$1)) -> 0 | M4: {=IF(H4="","",SUMif(year(N$2:BO$2),M$2,N4:BO4))} -> 0 | N4: 0.63 | O4: 3.5 | P4: 5 | Q4: 5
A5: A | B5: STL | C5: ПП | D5: t&m | E5: Жигалова | F5: Жигалова T&M | G5: Тригкред (Жигалова) | H5: Тригкред (Жигалова) | I5: Ярошевич Анжела | J5: Альмухаметова Татьяна | K5: =if(H5="","",NOT(ISNA(VLOOKUP(J5,'Команда'!G:G,1,false)))) -> TRUE | L5: =if(H5="","",sumifs(N5:BO5,N$2:BO$2,">"&$L$1)) -> 0 | M5: {=IF(H5="","",SUMif(year(N$2:BO$2),M$2,N5:BO5))} -> 247 | N5: 17 | O5: 20 | P5: 21 | Q5: 22 | R5: 18 | S5: 19 | T5: 20 | U5: 21 | V5: 22 | W5: 13 | X5: 9 | Y5: 22 | Z5: 15 | AA5: 19 | AB5: 21 | AC5: 22 | AD5: 19 | AE5: 21 | AF5: 23 | AG5: 21 | AH5: 22 | AI5: 22 | AJ5: 20 | AK5: 22
A6: D | B6: AN5 | C6: ПП | D6: fix | E6: Горшенина+Яковлева | F6: Горшенина+Яковлева FIX | G6: ЕИС FIX (Горшенина) | H6: ЕИС FIX (Горшенина) | I6: Бакулевская Алина | J6: Анисимов Николай | K6: =if(H6="","",NOT(ISNA(VLOOKUP(J6,'Команда'!G:G,1,false)))) -> TRUE | L6: =if(H6="","",sumifs(N6:BO6,N$2:BO$2,">"&$L$1)) -> 0 | M6: {=IF(H6="","",SUMif(year(N$2:BO$2),M$2,N6:BO6))} -> 117 | N6: 17 | O6: 20 | P6: 21 | Q6: 22 | R6: 18 | S6: 19 | T6: 23 | U6: 21 | V6: 22 | W6: 23 | X6: 19 | Y6: 22 | Z6: 15 | AA6: 19 | AB6: 21 | AC6: 22 | AD6: 19 | AE6: 21
A7: PM | B7: PM | C7: ПП | D7: fix | E7: Горшенина+Яковлева | F7: Горшенина+Яковлева FIX | G7: ЕИС FIX (Горшенина) | H7: ЕИС FIX (Горшенина) | I7: Бакулевская Алина | J7: Бакулевская Алина | K7: =if(H7="","",NOT(ISNA(VLOOKUP(J7,'Команда'!G:G,1,false)))) -> TRUE | L7: =if(H7="","",sumifs(N7:BO7,N$2:BO$2,">"&$L$1)) -> 0 | M7: {=IF(H7="","",SUMif(year(N$2:BO$2),M$2,N7:BO7))} -> 117 | N7: 17 | O7: 20 | P7: 21 | Q7: 22 | R7: 18 | S7: 19 | T7: 23 | U7: 21 | V7: 22 | W7: 23 | X7: 19 | Y7: 22 | Z7: 15 | AA7: 19 | AB7: 21 | AC7: 22 | AD7: 19 | AE7: 21
A8: A | B8: jAn ACRM ACRM | C8: ПП | D8: fix | E8: ACRM | F8: ACRM Импортозамещение | G8: ACRM Импортозамещение (Борисевич) | H8: ACRM Импортозамещение (Борисевич) | I8: Яковлева Елена | J8: Баранова Анастасия | K8: =if(H8="","",NOT(ISNA(VLOOKUP(J8,'Команда'!G:G,1,false)))) -> TRUE | L8: =if(H8="","",sumifs(N8:BO8,N$2:BO$2,">"&$L$1)) -> 0 | M8: {=IF(H8="","",SUMif(year(N$2:BO$2),M$2,N8:BO8))} -> 247 | N8: 10.7 | O8: 17.4 | P8: 18 | Q8: 21 | R8: 17.6 | S8: 8.55 | T8: 0.7 | U8: 8 | V8: 1.8 | Y8: 22 | Z8: 15 | AA8: 19 | AB8: 21 | AC8: 22 | AD8: 19 | AE8: 21 | AF8: 23 | AG8: 21 | AH8: 22 | AI8: 22 | AJ8: 20 | AK8: 22
A9: A | B9: STL2 | C9: ПП | D9: t&m | E9: Забияка | F9: Забияка T&M | G9: Управленческая отчетность сети РБ\ЗП (Забияка) | H9: Управленческая отчетность сети РБ\ЗП (Забияка) | I9: Ярошевич Анжела | J9: Болотова Алина | K9: =if(H9="","",NOT(ISNA(VLOOKUP(J9,'Команда'!G:G,1,false)))) -> TRUE | L9: =if(H9="","",sumifs(N9:BO9,N$2:BO$2,">"&$L$1)) -> 0 | M9: {=IF(H9="","",SUMif(year(N$2:BO$2),M$2,N9:BO9))} -> 0 | N9: 13 | O9: 19 | P9: 18 | Q9: 22 | R9: 13 | S9: 19 | T9: 16 | U9: 11 | V9: 22 | W9: 18 | X9: 19 | Y9: 11
A10: A | B10: AN5 | C10: ПП | D10: t&m | E10: Забияка | F10: Забияка T&M | G10: Мотивация сети РБ\ЗП (Забияка) | H10: Мотивация сети РБ\ЗП (Забияка) | I10: Ярошевич Анжела | J10: Ефименко Алёна | K10: =if(H10="","",NOT(ISNA(VLOOKUP(J10,'Команда'!G:G,1,false)))) -> TRUE | L10: =if(H10="","",sumifs(N10:BO10,N$2:BO$2,">"&$L$1)) -> 0 | M10: {=IF(H10="","",SUMif(year(N$2:BO$2),M$2,N10:BO10))} -> 0 | N10: 5
A11: D | B11: AN5 | C11: ПП | D11: fix | E11: Горшенина+Яковлева | F11: Горшенина+Яковлева FIX | G11: ЕИС FIX (Горшенина) | H11: ЕИС FIX (Горшенина) | I11: Бакулевская Алина | J11: Болдин-Илюхин Иван | K11: =if(H11="","",NOT(ISNA(VLOOKUP(J11,'Команда'!G:G,1,false)))) -> TRUE | L11: =if(H11="","",sumifs(N11:BO11,N$2:BO$2,">"&$L$1)) -> 0 | M11: {=IF(H11="","",SUMif(year(N$2:BO$2),M$2,N11:BO11))} -> 117 | N11: 17 | O11: 20 | P11: 21 | Q11: 22 | R11: 18 | S11: 19 | T11: 23 | U11: 21 | V11: 22 | W11: 23 | X11: 19 | Y11: 22 | Z11: 15 | AA11: 19 | AB11: 21 | AC11: 22 | AD11: 19 | AE11: 21
A12: D | B12: SD | C12: ПП | D12: fix | E12: Дворников | F12: Дворников FIX | G12: Миграция DWH на GP+Airflow FIX (Дворников) | H12: Миграция DWH на GP+Airflow FIX (Дворников) | I12: Клименко Алексей | J12: Куликовский Олег | K12: =if(H12="","",NOT(ISNA(VLOOKUP(J12,'Команда'!G:G,1,false)))) -> TRUE | L12: =if(H12="","",sumifs(N12:BO12,N$2:BO$2,">"&$L$1)) -> 0 | M12: {=IF(H12="","",SUMif(year(N$2:BO$2),M$2,N12:BO12))} -> 0 | N12: 17 | O12: 20 | P12: 21
A13: A | B13: STL2 | C13: ПП | D13: t&m | E13: Забияка | F13: Забияка T&M | G13: Мотивация сети РБ\ЗП (Забияка) | H13: Мотивация сети РБ\ЗП (Забияка) | I13: Ярошевич Анжела | J13: Пичугин Владислав | K13: =if(H13="","",NOT(ISNA(VLOOKUP(J13,'Команда'!G:G,1,false)))) -> TRUE | L13: =if(H13="","",sumifs(N13:BO13,N$2:BO$2,">"&$L$1)) -> 0 | M13: {=IF(H13="","",SUMif(year(N$2:BO$2),M$2,N13:BO13))} -> 0 | N13: 17 | O13: 20 | P13: 21 | Q13: 14 | R13: 18 | S13: 19 | T13: 23 | U13: 21 | V13: 22 | W13: 23 | X13: 9
A14: D | B14: An | C14: ПП | D14: t&m | E14: Шахов | F14: Шахов T&M | G14: PUMA (Шахов) | H14: PUMA (Каменецких) | I14: Иванюк Полина | J14: Бутков Евгений | K14: =if(H14="","",NOT(ISNA(VLOOKUP(J14,'Команда'!G:G,1,false)))) -> TRUE | L14: =if(H14="","",sumifs(N14:BO14,N$2:BO$2,">"&$L$1)) -> 0 | M14: {=IF(H14="","",SUMif(year(N$2:BO$2),M$2,N14:BO14))} -> 34 | U14: 8 | V14: 21 | W14: 16 | X14: 13 | Y14: 22 | Z14: 15 | AA14: 19
A15: D | B15: STL3 | C15: ПП | D15: t&m | E15: Маточкин | F15: Маточкин T&M | G15: Отчетность СБ (Маточкин) | H15: Отчетность СБ (Маточкин) | I15: Максимова Анастасия | J15: Плахов Игорь | K15: =if(H15="","",NOT(ISNA(VLOOKUP(J15,'Команда'!G:G,1,false)))) -> TRUE | L15: =if(H15="","",sumifs(N15:BO15,N$2:BO$2,">"&$L$1)) -> 0 | M15: {=IF(H15="","",SUMif(year(N$2:BO$2),M$2,N15:BO15))} -> 247 | N15: 17 | O15: 19 | P15: 21 | Q15: 22 | R15: 18 | S15: 19 | T15: 23 | U15: 21 | V15: 22 | W15: 23 | X15: 19 | Y15: 22 | Z15: 15 | AA15: 19 | AB15: 21 | AC15: 22 | AD15: 19 | AE15: 21 | AF15: 23 | AG15: 21 | AH15: 22 | AI15: 22 | AJ15: 20 | AK15: 22
A16: A | B16: SAn | C16: ПП | D16: t&m | E16: Маточкин | F16: Маточкин T&M | G16: Отчетность СБ (Маточкин) | H16: Отчетность СБ (Маточкин) | I16: Максимова Анастасия | J16: Тимофейчик Роман | K16: =if(H16="","",NOT(ISNA(VLOOKUP(J16,'Команда'!G:G,1,false)))) -> TRUE | L16: =if(H16="","",sumifs(N16:BO16,N$2:BO$2,">"&$L$1)) -> 0 | M16: {=IF(H16="","",SUMif(year(N$2:BO$2),M$2,N16:BO16))} -> 247 | N16: 17 | O16: 20 | P16: 21 | Q16: 22 | R16: 18 | S16: 19 | T16: 23 | U16: 21 | V16: 22 | W16: 23 | X16: 19 | Y16: 22 | Z16: 15 | AA16: 19 | AB16: 21 | AC16: 22 | AD16: 19 | AE16: 21 | AF16: 23 | AG16: 21 | AH16: 22 | AI16: 22 | AJ16: 20 | AK16: 22
A17: D | B17: Arch ACRM | C17: ПП | D17: fix | E17: ACRM | F17: ACRM FIX | G17: ACRM FIX (Борисевич) | H17: ACRM FIX (Борисевич) | I17: Яковлева Елена | J17: Морозов Дмитрий | K17: =if(H17="","",NOT(ISNA(VLOOKUP(J17,'Команда'!G:G,1,false)))) -> TRUE | L17: =if(H17="","",sumifs(N17:BO17,N$2:BO$2,">"&$L$1)) -> 0 | M17: {=IF(H17="","",SUMif(year(N$2:BO$2),M$2,N17:BO17))} -> 0 | P17: 4.6 | Q17: 5.5 | R17: 1.8 | S17: 4.2 | T17: 3.9 | U17: 5.2 | V17: 7.3 | W17: 5.75 | X17: 4.75 | Y17: 5.5
A18: D | B18: Arch ACRM | C18: ПП | D18: fix | E18: ACRM | F18: ACRM Support | G18: ACRM Support (Борисевич) | H18: ACRM Support (Борисевич) | I18: Яковлева Елена | J18: Морозов Дмитрий | K18: =if(H18="","",NOT(ISNA(VLOOKUP(J18,'Команда'!G:G,1,false)))) -> TRUE | L18: =if(H18="","",sumifs(N18:BO18,N$2:BO$2,">"&$L$1)) -> 0 | M18: {=IF(H18="","",SUMif(year(N$2:BO$2),M$2,N18:BO18))} -> 0 | W18: 6 | X18: 7 | Y18: 7
A19: D | B19: SD ACRM | C19: ПП | D19: fix | E19: ACRM | F19: ACRM Support | G19: ACRM Support (Борисевич) | H19: ACRM Support (Борисевич) | I19: Яковлева Елена | J19: Никитин Владимир | K19: =if(H19="","",NOT(ISNA(VLOOKUP(J19,'Команда'!G:G,1,false)))) -> TRUE | L19: =if(H19="","",sumifs(N19:BO19,N$2:BO$2,">"&$L$1)) -> 0 | M19: {=IF(H19="","",SUMif(year(N$2:BO$2),M$2,N19:BO19))} -> 0 | N19: 0.88 | O19: 0.13 | Q19: 1
A20: D | B20: SD ACRM | C20: ПП | D20: fix | E20: ACRM | F20: ACRM Импортозамещение | G20: ACRM Импортозамещение (Борисевич) | H20: ACRM Импортозамещение (Борисевич) | I20: Яковлева Елена | J20: Никитин Владимир | K20: =if(H20="","",NOT(ISNA(VLOOKUP(J20,'Команда'!G:G,1,false)))) -> TRUE | L20: =if(H20="","",sumifs(N20:BO20,N$2:BO$2,">"&$L$1)) -> 0 | M20: {=IF(H20="","",SUMif(year(N$2:BO$2),M$2,N20:BO20))} -> 0 | Q20: 5.5 | R20: 9 | S20: 9.5 | T20: 11.5 | U20: 10.5 | V20: 11 | W20: 8
A21: PM | B21: TL3 | C21: ПП | D21: t&m | E21: Жалненков | F21: Жалненков T&M | G21: DMDC (Жалненков) | H21: DMDC (Жалненков) | I21: Иванюк Полина | J21: Веденичев Игорь | K21: =if(H21="","",NOT(ISNA(VLOOKUP(J21,'Команда'!G:G,1,false)))) -> TRUE | L21: =if(H21="","",sumifs(N21:BO21,N$2:BO$2,">"&$L$1)) -> 0 | M21: {=IF(H21="","",SUMif(year(N$2:BO$2),M$2,N21:BO21))} -> 34 | W21: 21 | X21: 8 | Y21: 8 | Z21: 15 | AA21: 19
A22: PM | B22: TL3 | C22: ПП | D22: t&m | E22: Матвейкина | F22: Матвейкина T&M | G22: АСУ Налоги (Матвейкина) | H22: АСУ Налоги | I22: Веденичев Игорь | J22: Веденичев Игорь | K22: =if(H22="","",NOT(ISNA(VLOOKUP(J22,'Команда'!G:G,1,false)))) -> TRUE | L22: =if(H22="","",sumifs(N22:BO22,N$2:BO$2,">"&$L$1)) -> 0 | M22: {=IF(H22="","",SUMif(year(N$2:BO$2),M$2,N22:BO22))} -> 16 | U22: 0.8 | V22: 2 | W22: 4 | X22: 4 | Y22: 4 | Z22: 4 | AA22: 4 | AB22: 4 | AC22: 4
A23: D | B23: jD ACRM | C23: ПП | D23: fix | E23: ACRM | F23: ACRM Импортозамещение | G23: ACRM Импортозамещение (Борисевич) | H23: ACRM Импортозамещение (Борисевич) | I23: Яковлева Елена | J23: Рогов Юрий | K23: =if(H23="","",NOT(ISNA(VLOOKUP(J23,'Команда'!G:G,1,false)))) -> TRUE | L23: =if(H23="","",sumifs(N23:BO23,N$2:BO$2,">"&$L$1)) -> 0 | M23: {=IF(H23="","",SUMif(year(N$2:BO$2),M$2,N23:BO23))} -> 0
A24: A | B24: jAn1 | C24: ПП | D24: t&m | E24: Шергунов | F24: Шергунов T&M | G24: Доработки ALM (Трифонова) | H24: Доработки ALM (Трифонова) | I24: Ярошевич Анжела | J24: Великоборец Мария | K24: =if(H24="","",NOT(ISNA(VLOOKUP(J24,'Команда'!G:G,1,false)))) -> TRUE | L24: =if(H24="","",sumifs(N24:BO24,N$2:BO$2,">"&$L$1)) -> 0 | M24: {=IF(H24="","",SUMif(year(N$2:BO$2),M$2,N24:BO24))} -> 247 | N24: 17 | O24: 19 | P24: 21 | Q24: 22 | R24: 18 | S24: 19 | T24: 13 | U24: 21 | V24: 22 | W24: 18 | X24: 19 | Y24: 22 | Z24: 15 | AA24: 19 | AB24: 21 | AC24: 22 | AD24: 19 | AE24: 21 | AF24: 23 | AG24: 21 | AH24: 22 | AI24: 22 | AJ24: 20 | AK24: 22
A25: A | B25: AN5 | C25: ПП | D25: fix | E25: Горшенина+Яковлева | F25: Горшенина+Яковлева FIX | G25: Горшенина+Яковлева агрегатор (FIX) | H25: Горшенина+Яковлева агрегатор (FIX) | I25: Максимова Анастасия | J25: Волков Никита | K25: =if(H25="","",NOT(ISNA(VLOOKUP(J25,'Команда'!G:G,1,false)))) -> TRUE | L25: =if(H25="","",sumifs(N25:BO25,N$2:BO$2,">"&$L$1)) -> 0 | M25: {=IF(H25="","",SUMif(year(N$2:BO$2),M$2,N25:BO25))} -> 117 | S25: 19 | T25: 23 | U25: 21 | V25: 22 | W25: 23 | X25: 19 | Y25: 22 | Z25: 15 | AA25: 19 | AB25: 21 | AC25: 22 | AD25: 19 | AE25: 21
A26: A | B26: SAn | C26: ПП | D26: t&m | E26: Герасимов | F26: Герасимов T&M | G26: Mass Управленческая отчетность (Герасимов) | H26: Mass Управленческая отчетность (Герасимов) | I26: Максимова Анастасия | J26: Пронин Владимир | K26: =if(H26="","",NOT(ISNA(VLOOKUP(J26,'Команда'!G:G,1,false)))) -> TRUE | L26: =if(H26="","",sumifs(N26:BO26,N$2:BO$2,">"&$L$1)) -> 0 | M26: {=IF(H26="","",SUMif(year(N$2:BO$2),M$2,N26:BO26))} -> 247 | N26: 17 | O26: 20 | P26: 21 | Q26: 17 | R26: 18 | S26: 9 | T26: 23 | U26: 21 | V26: 22 | W26: 18 | X26: 19 | Y26: 22 | Z26: 15 | AA26: 19 | AB26: 21 | AC26: 22 | AD26: 19 | AE26: 21 | AF26: 23 | AG26: 21 | AH26: 22 | AI26: 22 | AJ26: 20 | AK26: 22
A27: D | B27: SD | C27: ПП | D27: t&m | E27: Герасимов | F27: Герасимов T&M | G27: Mass Управленческая отчетность (Герасимов) | H27: Mass Управленческая отчетность (Герасимов) | I27: Максимова Анастасия | J27: Гринченко Елена | K27: TRUE | L27: =if(H27="","",sumifs(N27:BO27,N$2:BO$2,">"&$L$1)) -> 0 | M27: {=IF(H27="","",SUMif(year(N$2:BO$2),M$2,N27:BO27))} -> 247 | N27: 17 | O27: 20 | P27: 21 | Q27: 17 | R27: 18 | S27: 9 | T27: 23 | U27: 21 | V27: 22 | W27: 18 | X27: 19 | Y27: 22 | Z27: 15 | AA27: 19 | AB27: 21 | AC27: 22 | AD27: 19 | AE27: 21 | AF27: 23 | AG27: 21 | AH27: 22 | AI27: 22 | AJ27: 20 | AK27: 22
A28: A | B28: STL (new) | C28: ПП | D28: t&m | E28: Герасимов | F28: Герасимов T&M | G28: Mass Управленческая отчетность (Герасимов) | H28: Mass Управленческая отчетность (Герасимов) | I28: Максимова Анастасия | J28: Романовская Жанна | K28: =if(H28="","",NOT(ISNA(VLOOKUP(J28,'Команда'!G:G,1,false)))) -> TRUE | L28: =if(H28="","",sumifs(N28:BO28,N$2:BO$2,">"&$L$1)) -> 0 | M28: {=IF(H28="","",SUMif(year(N$2:BO$2),M$2,N28:BO28))} -> 247 | N28: 17 | O28: 20 | P28: 21 | Q28: 22 | R28: 18 | S28: 14 | T28: 23 | U28: 21 | V28: 12 | W28: 18 | X28: 17 | Y28: 22 | Z28: 15 | AA28: 19 | AB28: 21 | AC28: 22 | AD28: 19 | AE28: 21 | AF28: 23 | AG28: 21 | AH28: 22 | AI28: 22 | AJ28: 20 | AK28: 22
A29: D | B29: STL5 | C29: ПП | D29: fix | E29: Дворников | F29: Дворников FIX | G29: Миграция DWH на GP+Airflow FIX (Дворников) | H29: Миграция DWH на GP+Airflow FIX (Дворников) | I29: Клименко Алексей | J29: Ушков Иван | K29: =if(H29="","",NOT(ISNA(VLOOKUP(J29,'Команда'!G:G,1,false)))) -> TRUE | L29: =if(H29="","",sumifs(N29:BO29,N$2:BO$2,">"&$L$1)) -> 0 | M29: {=IF(H29="","",SUMif(year(N$2:BO$2),M$2,N29:BO29))} -> 5 | N29: 3 | O29: 3 | P29: 3 | W29: 10 | X29: 9 | Y29: 10 | Z29: 2 | AA29: 3
A30: A | B30: SAN | C30: ПП | D30: t&m | E30: Забияка | F30: Забияка T&M | G30: Ускорение отчетности (Забияка) | H30: Ускорение отчетности (Забияка) | I30: Ярошевич Анжела | J30: Волченков Виталий | K30: =if(H30="","",NOT(ISNA(VLOOKUP(J30,'Команда'!G:G,1,false)))) -> TRUE | L30: =if(H30="","",sumifs(N30:BO30,N$2:BO$2,">"&$L$1)) -> 0 | M30: {=IF(H30="","",SUMif(year(N$2:BO$2),M$2,N30:BO30))} -> 55 | N30: 17 | O30: 19 | P30: 20 | Q30: 17 | R30: 17 | S30: 19 | T30: 18 | U30: 21 | V30: 22 | W30: 13 | X30: 17 | Y30: 19 | Z30: 15 | AA30: 19 | AB30: 21
A31: A | B31: MAn2 | C31: ПП | D31: fix | E31: Аронова | F31: Аронова FIX | G31: Миграция RWA FIX (Аронова) | H31: Миграция RWA FIX (Аронова) | I31: Клименко Алексей | J31: Габдуллин Адель | K31: =if(H31="","",NOT(ISNA(VLOOKUP(J31,'Команда'!G:G,1,false)))) -> TRUE | L31: =if(H31="","",sumifs(N31:BO31,N$2:BO$2,">"&$L$1)) -> 0 | M31: {=IF(H31="","",SUMif(year(N$2:BO$2),M$2,N31:BO31))} -> 34 | Z31: 15 | AA31: 19
A32: A | B32: STL | C32: ПП | D32: t&m | E32: Овсянников | F32: Овсянников T&M | G32: Финансы (Овсянников) | H32: Финансы (Овсянников) | I32: Иванюк Полина | J32: Гиряев Антон | K32: =if(H32="","",NOT(ISNA(VLOOKUP(J32,'Команда'!G:G,1,false)))) -> TRUE | L32: =if(H32="","",sumifs(N32:BO32,N$2:BO$2,">"&$L$1)) -> 0 | M32: {=IF(H32="","",SUMif(year(N$2:BO$2),M$2,N32:BO32))} -> 34 | N32: 16.99 | O32: 13.8 | P32: 19.71 | Q32: 22 | R32: 15 | S32: 18 | T32: 22 | U32: 11 | V32: 20 | W32: 22 | X32: 19 | Y32: 21 | Z32: 15 | AA32: 19
A33: A | B33: SAn ACRM | C33: ПП | D33: t&m | E33: ACRM | F33: ACRM T&M | G33: ACRM Задачи T&M (Борисевич) | H33: ACRM Задачи T&M (Борисевич) | I33: Ярошевич Анжела | J33: Цуба Виктория | K33: =if(H33="","",NOT(ISNA(VLOOKUP(J33,'Команда'!G:G,1,false)))) -> TRUE | L33: =if(H33="","",sumifs(N33:BO33,N$2:BO$2,">"&$L$1)) -> 0 | M33: {=IF(H33="","",SUMif(year(N$2:BO$2),M$2,N33:BO33))} -> 0 | N33: 19.88 | O33: 15.94 | P33: 5.6 | Q33: 7
A34: A | B34: AN ACRM | C34: ПП | D34: fix | E34: ACRM | F34: ACRM FIX | G34: ACRM FIX (Борисевич) | H34: ACRM FIX (Борисевич) | I34: Яковлева Елена | J34: Часовская Алина | K34: =if(H34="","",NOT(ISNA(VLOOKUP(J34,'Команда'!G:G,1,false)))) -> TRUE | L34: =if(H34="","",sumifs(N34:BO34,N$2:BO$2,">"&$L$1)) -> 0 | M34: {=IF(H34="","",SUMif(year(N$2:BO$2),M$2,N34:BO34))} -> 0 | N34: 7 | O34: 6.4 | P34: 4.6 | Q34: 0.7 | S34: 4.2 | T34: 20.2 | U34: 8.4 | V34: 9.7 | W34: 11.5 | X34: 9.5 | Y34: 11
A35: A | B35: Indiv AN | C35: ПП | D35: t&m | E35: Шергунов | F35: Шергунов T&M | G35: РКТ (Иванова) | H35: РКТ (Иванова) | I35: Ярошевич Анжела | J35: Гродзь Анастасия | K35: =if(H35="","",NOT(ISNA(VLOOKUP(J35,'Команда'!G:G,1,false)))) -> TRUE | L35: =if(H35="","",sumifs(N35:BO35,N$2:BO$2,">"&$L$1)) -> 0 | M35: {=IF(H35="","",SUMif(year(N$2:BO$2),M$2,N35:BO35))} -> 55 | V35: 12 | W35: 23 | X35: 19 | Y35: 22 | Z35: 15 | AA35: 19 | AB35: 21
A36: A | B36: STL | C36: ПП | D36: t&m | E36: Мельник | F36: Мельник T&M | G36: VoC T&M (Мельник) | H36: VoC T&M (Мельник) | I36: Иванюк Полина | J36: Гусева Жанна | K36: =if(H36="","",NOT(ISNA(VLOOKUP(J36,'Команда'!G:G,1,false)))) -> TRUE | L36: =if(H36="","",sumifs(N36:BO36,N$2:BO$2,">"&$L$1)) -> 0 | M36: {=IF(H36="","",SUMif(year(N$2:BO$2),M$2,N36:BO36))} -> 34 | Z36: 15 | AA36: 19
A37: D | B37: STL | C37: ПП | D37: fix | E37: Дворников | F37: Дворников FIX | G37: Миграция DWH на GP+Airflow FIX (Дворников) | H37: Миграция DWH на GP+Airflow FIX (Дворников) | I37: Клименко Алексей | J37: Даровская Анастасия | K37: =if(H37="","",NOT(ISNA(VLOOKUP(J37,'Команда'!G:G,1,false)))) -> TRUE | L37: =if(H37="","",sumifs(N37:BO37,N$2:BO$2,">"&$L$1)) -> 0 | M37: {=IF(H37="","",SUMif(year(N$2:BO$2),M$2,N37:BO37))} -> 44 | N37: 17 | O37: 20 | P37: 21 | Q37: 22 | R37: 18 | W37: 23 | X37: 19 | Y37: 22 | Z37: 15 | AA37: 19 | AB37: 5 | AC37: 5
A38: D | B38: SD ACRM | C38: ПП | D38: fix | E38: ACRM | F38: ACRM Импортозамещение | G38: ACRM Импортозамещение (Борисевич) | H38: ACRM Импортозамещение (Борисевич) | I38: Яковлева Елена | J38: Молоденов Константин | K38: =if(H38="","",NOT(ISNA(VLOOKUP(J38,'Команда'!G:G,1,false)))) -> TRUE | L38: =if(H38="","",sumifs(N38:BO38,N$2:BO$2,">"&$L$1)) -> 0 | M38: {=IF(H38="","",SUMif(year(N$2:BO$2),M$2,N38:BO38))} -> 0 | N38: 12.6 | O38: 14 | P38: 13.2 | Q38: 20 | R38: 15 | S38: 14 | T38: 18.6 | U38: 18.9 | V38: 15.4
A39: A | B39: jD ACRM | C39: ПП | D39: fix | E39: ACRM | F39: ACRM Импортозамещение | G39: ACRM Импортозамещение (Борисевич) | H39: ACRM Импортозамещение (Борисевич) | I39: Яковлева Елена | J39: Алексеев Андрей | K39: =if(H39="","",NOT(ISNA(VLOOKUP(J39,'Команда'!G:G,1,false)))) -> TRUE | L39: =if(H39="","",sumifs(N39:BO39,N$2:BO$2,">"&$L$1)) -> 0 | M39: {=IF(H39="","",SUMif(year(N$2:BO$2),M$2,N39:BO39))} -> 0 | N39: 14.38 | O39: 19.31 | P39: 13.31 | Q39: 20.2 | R39: 14.4 | S39: 15.4 | T39: 2.8 | U39: 3.6 | V39: 15.4 | W39: 23
A40: BI | B40: MD | C40: BI | D40: t&m | E40: Мельник | F40: Мельник T&M | G40: VoC T&M (Мельник) | H40: VoC T&M (Мельник) | I40: Иванюк Полина | J40: Сорокина Дания | K40: =if(H40="","",NOT(ISNA(VLOOKUP(J40,'Команда'!G:G,1,false)))) -> TRUE | L40: =if(H40="","",sumifs(N40:BO40,N$2:BO$2,">"&$L$1)) -> 0 | M40: {=IF(H40="","",SUMif(year(N$2:BO$2),M$2,N40:BO40))} -> 0 | N40: 1.64 | O40: 8.42 | P40: 5.97 | Q40: 3.5 | R40: 1 | S40: 1.38 | U40: 3.64 | V40: 1 | W40: 1 | X40: 1 | Y40: 1
...
